<?xml version="1.0" ?>
<!-- =================================================================================== -->
<!-- |    This document was autogenerated by xacro from /home/lucas/Desktop/robotics/natural_language_hubert/src/hubert_kinematics/urdf/test_robot.urdf.xacro | -->
<!-- |    EDITING THIS FILE BY HAND IS NOT RECOMMENDED                                 | -->
<!-- =================================================================================== -->
<robot name="hubert_robot">
    <material name="white">
        <color rgba="1 1 1 1" />
    </material>
    <link name="world" />
    <joint name="world_joint" type="fixed">
        <origin rpy="0 0 0" xyz="0 0 0" />
        <parent link="world" />
        <child link="base_link" />
    </joint>
    <link name="base_link">
        <visual>
            <origin rpy="0 0 0" xyz="0 0 0.0275" />
            <geometry>
                <box size="0.08 0.08 0.055" />
            </geometry>
            <material name="white" />
        </visual>
        <collision>
            <origin rpy="0 0 0" xyz="0 0 0.0275" />
            <geometry>
                <box size="0.08 0.08 0.055" />
            </geometry>
        </collision>
        <inertial>
            <origin rpy="0 0 0" xyz="0 0 0.0275" />
            <mass value="0.5" />
            <inertia ixx="0.0003927083333333333" ixy="0.0" ixz="0.0" iyy="0.0003927083333333333" iyz="0.0" izz="0.0005333333333333334" />
        </inertial>
    </link>
    <joint name="base_joint" type="revolute">
        <parent link="base_link" />
        <child link="body_link" />
        <origin rpy="0 0 0" xyz="0 0 0.055" />
        <axis xyz="0 0 1" />
        <limit effort="100" lower="-1.5707963267948966" upper="1.5707963267948966" velocity="100" />
    </joint>
    <link name="body_link">
        <visual>
            <origin rpy="0 0 0" xyz="0 0 0.1575" />
            <geometry>
                <box size="0.03 0.05 0.315" />
            </geometry>
            <material name="white" />
        </visual>
        <collision>
            <origin rpy="0 0 0" xyz="0 0 0.1575" />
            <geometry>
                <box size="0.03 0.05 0.315" />
            </geometry>
        </collision>
        <inertial>
            <origin rpy="0 0 0" xyz="0 0 0.1575" />
            <mass value="0.5" />
            <inertia ixx="0.0042385416666666665" ixy="0.0" ixz="0.0" iyy="0.004171875" iyz="0.0" izz="0.00014166666666666668" />
        </inertial>
    </link>
    <joint name="chest_joint" type="fixed">
        <parent link="body_link" />
        <child link="shoulder_link" />
        <origin rpy="0 0 0" xyz="0 0 0.315" />
    </joint>
    <link name="shoulder_link">
        <visual>
            <origin rpy="0 0 0" xyz="0 0 0.0125" />
            <geometry>
                <box size="0.04 0.24 0.025" />
            </geometry>
            <material name="white" />
        </visual>
        <collision>
            <origin rpy="0 0 0" xyz="0 0 0.0125" />
            <geometry>
                <box size="0.04 0.24 0.025" />
            </geometry>
        </collision>
        <inertial>
            <origin rpy="0 0 0" xyz="0 0 0.0125" />
            <mass value="0.5" />
            <inertia ixx="0.0024260416666666666" ixy="0.0" ixz="0.0" iyy="9.270833333333334e-05" iyz="0.0" izz="0.0024666666666666665" />
        </inertial>
    </link>
    <joint name="neck_joint" type="revolute">
        <parent link="shoulder_link" />
        <child link="neck_link" />
        <origin rpy="0 0 0" xyz="0 0 0.025" />
        <axis xyz="0 0 1" />
        <limit effort="100" lower="-1.5707963267948966" upper="1.5707963267948966" velocity="100" />
    </joint>
    <link name="neck_link">
        <visual>
            <origin rpy="0 0 0" xyz="0 0 0.0325" />
            <geometry>
                <box size="0.05 0.05 0.065" />
            </geometry>
            <material name="white" />
        </visual>
        <collision>
            <origin rpy="0 0 0" xyz="0 0 0.0325" />
            <geometry>
                <box size="0.05 0.05 0.065" />
            </geometry>
        </collision>
        <inertial>
            <origin rpy="0 0 0" xyz="0 0 0.0325" />
            <mass value="0.5" />
            <inertia ixx="0.00028020833333333337" ixy="0.0" ixz="0.0" iyy="0.00028020833333333337" iyz="0.0" izz="0.00020833333333333337" />
        </inertial>
    </link>
    <joint name="cam_joint" type="revolute">
        <parent link="neck_link" />
        <child link="cam_link" />
        <origin rpy="-1.57 0 0" xyz="0 0 0.065" />
        <axis xyz="0 0 1" />
        <limit effort="100" lower="-0.7853981633974483" upper="1.5707963267948966" velocity="100" />
    </joint>
    <!-- Here z => y and y => -z -->
    <link name="cam_link">
        <visual>
            <origin rpy="0 0 0" xyz="0 -0.0325 0" />
            <geometry>
                <box size="0.05 -0.065 0.08" />
            </geometry>
            <material name="white" />
        </visual>
        <collision>
            <origin rpy="0 0 0" xyz="0 -0.0325 0" />
            <geometry>
                <box size="0.05 0.065 0.08" />
            </geometry>
        </collision>
        <inertial>
            <origin rpy="0 0 0" xyz="0 -0.0325 0" />
            <mass value="0.5" />
            <inertia ixx="0.00044270833333333337" ixy="0.0" ixz="0.0" iyy="0.00037083333333333337" iyz="0.0" izz="0.00028020833333333337" />
        </inertial>
    </link>
    <joint name="shoulder_joint" type="revolute">
        <parent link="shoulder_link" />
        <child link="arm_link" />
        <origin rpy="1.57 0 0" xyz="0.034 -0.108 0.045" />
        <axis xyz="0 0 1" />
        <limit effort="100" lower="-0.5235987755982988" upper="1.5707963267948966" velocity="100" />
    </joint>
    <link name="arm_link">
        <visual>
            <origin rpy="0 0 0" xyz="0 -0.044 0" />
            <geometry>
                <box size="0.025 0.088 0.025" />
            </geometry>
            <material name="white" />
        </visual>
        <collision>
            <origin rpy="0 0 0" xyz="0 -0.044 0" />
            <geometry>
                <box size="0.025 0.088 0.025" />
            </geometry>
        </collision>
        <inertial>
            <origin rpy="0 0 0" xyz="0 -0.044 0" />
            <mass value="0.5" />
            <inertia ixx="0.0003487083333333333" ixy="0.0" ixz="0.0" iyy="5.2083333333333343e-05" iyz="0.0" izz="0.0003487083333333333" />
        </inertial>
    </link>
    <!-- Origin values to modify -->
    <!-- Should the origin be rotated again as the last joint already is? -->
    <joint name="elbow_joint" type="revolute">
        <parent link="arm_link" />
        <child link="forearm_link" />
        <origin rpy="0 0 0" xyz="0.015 -0.088 -0.005" />
        <axis xyz="0 0 1" />
        <limit effort="100" lower="-1.5707963267948966" upper="1.5707963267948966" velocity="100" />
    </joint>
    <link name="forearm_link">
        <visual>
            <origin rpy="0 0 0" xyz="0 -0.075 0 " />
            <geometry>
                <box size="0.025 0.15 0.025" />
            </geometry>
            <material name="white" />
        </visual>
        <collision>
            <origin rpy="0 0 0" xyz="0 -0.075 0" />
            <geometry>
                <box size="0.025 0.15 0.025" />
            </geometry>
        </collision>
        <inertial>
            <origin rpy="0 0 0" xyz="0 0 -0.102" />
            <mass value="0.5" />
            <inertia ixx="0.0017600416666666663" ixy="0.0" ixz="0.0" iyy="0.0017600416666666663" iyz="0.0" izz="5.2083333333333343e-05" />
        </inertial>
    </link>
    <!-- Axis values to modify -->
    <joint name="end_joint" type="fixed">
        <parent link="forearm_link" />
        <child link="end_effector" />
        <origin rpy="0 0 0" xyz="0 -0.15 0" />
        <axis xyz="0 0 0" />
    </joint>
    <link name="end_effector">
        <visual>
            <origin rpy="0 0 0" xyz="0 -0.0125 0" />
            <geometry>
                <box size="0.025 0.025 0.05" />
            </geometry>
            <material name="white" />
        </visual>
        <collision>
            <origin rpy="0 0 0" xyz="0 -0.0125 0" />
            <geometry>
                <box size="0.025 0.025 0.05" />
            </geometry>
        </collision>
        <inertial>
            <origin rpy="0 0 0" xyz="0 -0.0125 0" />
            <mass value="0.5" />
            <inertia ixx="0.00013020833333333336" ixy="0.0" ixz="0.0" iyy="0.00013020833333333336" iyz="0.0" izz="5.2083333333333343e-05" />
        </inertial>
    </link>
    <transmission name="trans_base_joint">
        <type>transmission_interface/SimpleTransmission</type>
        <joint name="base_joint">
            <hardwareInterface>hardware_interface/EffortJointInterface</hardwareInterface>
        </joint>
        <actuator name="base_joint_motor">
            <hardwareInterface>hardware_interface/EffortJointInterface</hardwareInterface>
            <mechanicalReduction>1</mechanicalReduction>
        </actuator>
    </transmission>
    <transmission name="trans_neck_joint">
        <type>transmission_interface/SimpleTransmission</type>
        <joint name="neck_joint">
            <hardwareInterface>hardware_interface/EffortJointInterface</hardwareInterface>
        </joint>
        <actuator name="neck_joint_motor">
            <hardwareInterface>hardware_interface/EffortJointInterface</hardwareInterface>
            <mechanicalReduction>1</mechanicalReduction>
        </actuator>
    </transmission>
    <transmission name="trans_cam_joint">
        <type>transmission_interface/SimpleTransmission</type>
        <joint name="cam_joint">
            <hardwareInterface>hardware_interface/EffortJointInterface</hardwareInterface>
        </joint>
        <actuator name="cam_joint_motor">
            <hardwareInterface>hardware_interface/EffortJointInterface</hardwareInterface>
            <mechanicalReduction>1</mechanicalReduction>
        </actuator>
    </transmission>
    <transmission name="trans_shoulder_joint">
        <type>transmission_interface/SimpleTransmission</type>
        <joint name="shoulder_joint">
            <hardwareInterface>hardware_interface/EffortJointInterface</hardwareInterface>
        </joint>
        <actuator name="shoulder_joint_motor">
            <hardwareInterface>hardware_interface/EffortJointInterface</hardwareInterface>
            <mechanicalReduction>1</mechanicalReduction>
        </actuator>
    </transmission>
    <transmission name="trans_elbow_joint">
        <type>transmission_interface/SimpleTransmission</type>
        <joint name="elbow_joint">
            <hardwareInterface>hardware_interface/EffortJointInterface</hardwareInterface>
        </joint>
        <actuator name="elbow_joint_motor">
            <hardwareInterface>hardware_interface/EffortJointInterface</hardwareInterface>
            <mechanicalReduction>1</mechanicalReduction>
        </actuator>
    </transmission>
    <gazebo>
        <plugin name="gazebo_ros_control" filename="libgazebo_ros_control.so">
            <robotNamespace>/</robotNamespace>
        </plugin>
    </gazebo>
</robot>

